<?xml version="1.0" encoding="UTF-8"?>
<testng-results skipped="0" failed="2" total="2" passed="0">
  <reporter-output>
  </reporter-output>
  <suite name="Default suite" duration-ms="46390" started-at="2021-05-10T13:11:42Z" finished-at="2021-05-10T13:12:29Z">
    <groups>
    </groups>
    <test name="Default test" duration-ms="46390" started-at="2021-05-10T13:11:42Z" finished-at="2021-05-10T13:12:29Z">
      <class name="com.ortelligence.testpages.TestSignPage">
        <test-method status="FAIL" signature="testSignPage(java.lang.String, java.lang.String)[pri:0, instance:com.ortelligence.testpages.TestSignPage@20e2cbe0]" name="testSignPage" duration-ms="18926" started-at="2021-05-10T18:41:42Z" data-provider="testData" finished-at="2021-05-10T18:42:01Z">
          <params>
            <param index="0">
              <value>
                <![CDATA[QAHcpSurgeonOAFacilityOASystemOA@mailinator.com]]>
              </value>
            </param>
            <param index="1">
              <value>
                <![CDATA[ORT@3322]]>
              </value>
            </param>
          </params>
          <exception class="java.lang.AssertionError">
            <message>
              <![CDATA[expected [true] but found [false]]]>
            </message>
            <full-stacktrace>
              <![CDATA[java.lang.AssertionError: expected [true] but found [false]
	at org.testng.Assert.fail(Assert.java:94)
	at org.testng.Assert.failNotEquals(Assert.java:513)
	at org.testng.Assert.assertTrue(Assert.java:42)
	at org.testng.Assert.assertTrue(Assert.java:52)
	at com.ortelligence.testpages.TestSignPage.testSignPage(TestSignPage.java:24)
	at sun.reflect.NativeMethodAccessorImpl.invoke0(Native Method)
	at sun.reflect.NativeMethodAccessorImpl.invoke(Unknown Source)
	at sun.reflect.DelegatingMethodAccessorImpl.invoke(Unknown Source)
	at java.lang.reflect.Method.invoke(Unknown Source)
	at org.testng.internal.MethodInvocationHelper.invokeMethod(MethodInvocationHelper.java:100)
	at org.testng.internal.Invoker.invokeMethod(Invoker.java:646)
	at org.testng.internal.Invoker.invokeTestMethod(Invoker.java:811)
	at org.testng.internal.Invoker.invokeTestMethods(Invoker.java:1137)
	at org.testng.internal.TestMethodWorker.invokeTestMethods(TestMethodWorker.java:129)
	at org.testng.internal.TestMethodWorker.run(TestMethodWorker.java:112)
	at org.testng.TestRunner.privateRun(TestRunner.java:753)
	at org.testng.TestRunner.run(TestRunner.java:607)
	at org.testng.SuiteRunner.runTest(SuiteRunner.java:368)
	at org.testng.SuiteRunner.runSequentially(SuiteRunner.java:363)
	at org.testng.SuiteRunner.privateRun(SuiteRunner.java:321)
	at org.testng.SuiteRunner.run(SuiteRunner.java:270)
	at org.testng.SuiteRunnerWorker.runSuite(SuiteRunnerWorker.java:52)
	at org.testng.SuiteRunnerWorker.run(SuiteRunnerWorker.java:86)
	at org.testng.TestNG.runSuitesSequentially(TestNG.java:1284)
	at org.testng.TestNG.runSuitesLocally(TestNG.java:1209)
	at org.testng.TestNG.runSuites(TestNG.java:1124)
	at org.testng.TestNG.run(TestNG.java:1096)
	at org.testng.remote.AbstractRemoteTestNG.run(AbstractRemoteTestNG.java:132)
	at org.testng.remote.RemoteTestNG.initAndRun(RemoteTestNG.java:236)
	at org.testng.remote.RemoteTestNG.main(RemoteTestNG.java:81)
]]>
            </full-stacktrace>
          </exception> <!-- java.lang.AssertionError -->
          <reporter-output>
          </reporter-output>
        </test-method> <!-- testSignPage -->
        <test-method status="FAIL" signature="testSignPage(java.lang.String, java.lang.String)[pri:0, instance:com.ortelligence.testpages.TestSignPage@20e2cbe0]" name="testSignPage" duration-ms="27413" started-at="2021-05-10T18:42:01Z" data-provider="testData" finished-at="2021-05-10T18:42:29Z">
          <params>
            <param index="0">
              <value>
                <![CDATA[QASpdOAFacilityOASystemOA@mailinator.com]]>
              </value>
            </param>
            <param index="1">
              <value>
                <![CDATA[ORT@3322]]>
              </value>
            </param>
          </params>
          <exception class="java.lang.AssertionError">
            <message>
              <![CDATA[expected [true] but found [false]]]>
            </message>
            <full-stacktrace>
              <![CDATA[java.lang.AssertionError: expected [true] but found [false]
	at org.testng.Assert.fail(Assert.java:94)
	at org.testng.Assert.failNotEquals(Assert.java:513)
	at org.testng.Assert.assertTrue(Assert.java:42)
	at org.testng.Assert.assertTrue(Assert.java:52)
	at com.ortelligence.testpages.TestSignPage.testSignPage(TestSignPage.java:24)
	at sun.reflect.NativeMethodAccessorImpl.invoke0(Native Method)
	at sun.reflect.NativeMethodAccessorImpl.invoke(Unknown Source)
	at sun.reflect.DelegatingMethodAccessorImpl.invoke(Unknown Source)
	at java.lang.reflect.Method.invoke(Unknown Source)
	at org.testng.internal.MethodInvocationHelper.invokeMethod(MethodInvocationHelper.java:100)
	at org.testng.internal.Invoker.invokeMethod(Invoker.java:646)
	at org.testng.internal.Invoker.invokeTestMethod(Invoker.java:811)
	at org.testng.internal.Invoker.invokeTestMethods(Invoker.java:1137)
	at org.testng.internal.TestMethodWorker.invokeTestMethods(TestMethodWorker.java:129)
	at org.testng.internal.TestMethodWorker.run(TestMethodWorker.java:112)
	at org.testng.TestRunner.privateRun(TestRunner.java:753)
	at org.testng.TestRunner.run(TestRunner.java:607)
	at org.testng.SuiteRunner.runTest(SuiteRunner.java:368)
	at org.testng.SuiteRunner.runSequentially(SuiteRunner.java:363)
	at org.testng.SuiteRunner.privateRun(SuiteRunner.java:321)
	at org.testng.SuiteRunner.run(SuiteRunner.java:270)
	at org.testng.SuiteRunnerWorker.runSuite(SuiteRunnerWorker.java:52)
	at org.testng.SuiteRunnerWorker.run(SuiteRunnerWorker.java:86)
	at org.testng.TestNG.runSuitesSequentially(TestNG.java:1284)
	at org.testng.TestNG.runSuitesLocally(TestNG.java:1209)
	at org.testng.TestNG.runSuites(TestNG.java:1124)
	at org.testng.TestNG.run(TestNG.java:1096)
	at org.testng.remote.AbstractRemoteTestNG.run(AbstractRemoteTestNG.java:132)
	at org.testng.remote.RemoteTestNG.initAndRun(RemoteTestNG.java:236)
	at org.testng.remote.RemoteTestNG.main(RemoteTestNG.java:81)
]]>
            </full-stacktrace>
          </exception> <!-- java.lang.AssertionError -->
          <reporter-output>
          </reporter-output>
        </test-method> <!-- testSignPage -->
      </class> <!-- com.ortelligence.testpages.TestSignPage -->
    </test> <!-- Default test -->
  </suite> <!-- Default suite -->
</testng-results>
